# 栈展开和清除

当一段代码抛出异常时，控制会立即跳转至与该异常匹配的异常处理程序。这个异常处理程序可能位于栈中一个或几个函数调用上。当控制在栈中上跳时，这个过程称为栈展开（stack unwinding），当前执行点之后各函数中余下的所有代码都会跳过。不过，每个展开函数中的局部对象和变量会撤销，就好像代码正常地完成了这个函数一样。

## 栈展开导致的内存泄漏

在栈展开过程中，指针变量不会释放，也不会完成其他清除工作，可能会带来内存泄漏的问题。

```
#include <iostream>
#include <exception>
#include <fstream>
using namespace std;

void func1() throw(std::exception);
void func2() throw(std::exception);

int main()
{
	try {
		func1();
	} catch (std::exception) {
		cerr << "Exception caught.\n";
		return -1;
	}
}

void func1() throw(std::exception)
{
	string str1;
	string* str2 = new string("123");
	func2();
	delete str2;
}

void func2() throw(std::exception)
{
	ifstream infile;
	infile.open("filename");
	throw std::exception();
	infile.close();
}
```

当 func2() 抛出异常时，控制从
```
throw std::exception()
```
跳转到
```
cerr << "Exception caught.\n";
```
所以
```
infile.close();
```
不会得到执行，幸运的是因为 infile 是栈上的局部变量，这里会调用 ifstream 的析构函数关闭文件。

然而这段代码
```
delete str2;
```
不会执行，造成了内存泄漏。

下面有两种处理这种问题的技术。

### 捕获、清除和重新抛出

为避免内存泄漏和资源泄漏，我们让每个函数都尽可能捕获可能的异常，并完成必要的清除工作，再把异常重新抛给栈上更高的函数去处理。

修改后的 func1:

```
void func1() throw(std::exception)
{
	string str1;
	string* str2 = new string("123");
	try {
		func2();	
	} catch (...) { // 捕获任何异常
		delete str2;
		throw; // 重新抛出异常
	}
	delete str2;
}
```

将 func2 调用与异常处理程序包裹在一起，异常处理完成清除工作（delete str2），然后重新抛出异常。

### 使用智能指针

智能指针在栈上分配时，无论何时销毁，都会在底层哑指针上调用 delete。

修改后的 func1:

```
#include <memory>

void func1() throw(std::exception)
{
	string str1;
	shared_ptr<string> str2 (new string("123"));
	func2();
}
```